Workbook
Name Additives_Data: #REF!
Name Applications_Data: Applications!$A$1:$BD$500
Name Applicator_Data: #REF!
Name Crop_Data: #REF!
Name crop_year: #REF!
Name Farm_Data: #REF!
Name Field_Data: Customer_Data!$A$1:$P$115
Name operation_name: #REF!
Name Pest_Data: #REF!
Name Pesticide_Data: #REF!
Name Pesticide_List_Copy: #REF!
Name Pesticide_List_Criteria: #REF!
Name Pesticide_Type_Table: #REF!
Name PPE_Code_Table: #REF!
Name Variety_Data: #REF!

Sheet Main
A1: Time Out Lawncare LLC
A3: Operator: | B3: Time Out Lawncare LLC
A4: Year: | B4: 2024 | C4: 2025 | D4: 2026

Sheet Applications
A1: Customer Name | B1: Application Date | C1: Application Start Time | D1: Application End Time | E1: Applicator | F1: ID number | G1: Treatment Type | H1: Size of Area Treated | J1: Brand Name 1 | K1: Active Ingredients | L1: Rate per Acre | M1: Total Amount Applied (Oz) | N1: Brand Name 2 | O1: Active Ingredients | P1: Rate per Acre | Q1: Total Amount Applied (Oz) | R1: Brand Name 3 | S1: Active Ingredients | T1: Rate per Acre | U1: Total Amount Applied (Oz) | V1: Brand Name 4 | W1: Active Ingredients | X1: Rate per Acre | Y1: Total Amount Applied (Oz) | Z1: Brand Name 5 | AA1: Active Ingredients | AB1: Rate per Acre | AC1: Total Amount Applied (Oz) | AD1: Brand Name 6 | AE1: Active Ingredients | AF1: Rate per Acre | AG1: Total Amount Applied (Oz) | AH1: Additive | AI1: Rate per Acre | AJ1: Total Amount Applied (Oz) | AK1: Applic. Method | AL1: Applic. Equip. | AM1: Wind Dir. | AN1: Wind Speed | AO1: Temp. | AP1: Rel. Hum. | AQ1: Herbicide $/Unit of Product | AR1: Herbicide Cost | AS1: Herbicide Cost/Acre | AT1: Total Herbicide Cost | AU1: Total Herbicide Cost/Acre | AV1: Addit. 1 $/Unit of Product | AW1: Addit. 1 Cost | AX1: Addit. 1 Cost/Acre | AY1: Total Chemical Cost | AZ1: Total Chemical Cost/Acre | BA1: Total Applic. Cost | BB1: Total Applic. Cost/Acre | BC1: Total Cost | BD1: Total Cost/Acre
A2: Max Miller | B2: 45591 | C2: 0.5 | D2: =C2+0.0208333 -> 0.5208333 | E2: Matthew Stowers | F2: =IFERROR(VLOOKUP(E2,Data!A$2:B$5,2,TRUE), "") -> 48160 | G2: Fall (pre/post emerge) | H2: =IFERROR(VLOOKUP(A2,Customer_Data!$A$1:$P$114,8,TRUE),"") -> 3100 | J2: =IF($G2=("Fall (pre/post emerge)"),"Princep Liquid (100-526)", IF($G2=("Fertilize"),"Harrell's 34-0-5",IF($G2=("Spot Treat"),"Outrider (59639-223)",""))) -> Princep Liquid (100-526) | K2: Simazine | L2: 32 | M2: =L2*(H2/43560) -> 2.2773186 | N2: =IF($G2=("Fall (pre/post emerge)"),"Triplet SF (3-Way) 228-312",IF($G2=("Spring Preemerge (Jan)"),"Triplet SF (3-Way) 228-312",IF($G2=("Spring Preemerge (Apr)"),"Triplet SF (3-Way) 228-312",""))) -> Triplet SF (3-Way) 228-312 | O2: =VLOOKUP($N2,Herbicide_Data!$A$1:$L$61,9) -> 2,4-D, dimethylamine salt; Dicamba, dimethylamine salt;Mecoprop-p (MCPP-p), dimethylamine salt | P2: =VLOOKUP($N2,Herbicide_Data!$A$1:$L$61,12) -> 24 | Q2: =P2*($H2/43560) -> 1.707989 | R2: =IF($G2=("Fall (pre/post emerge)"),"Resolute 4Fl (100-1139)",IF($G2=("Spring Preemerge (Jan)"),"Resolute 4Fl (100-1139)",IF($G2=("Spring Preemerge (Apr)"),"Certinty Turf 59639-226",""))) -> Resolute 4Fl (100-1139) | S2: =VLOOKUP($R2,Herbicide_Data!$A$1:$L$61,9) -> Prodiamine | T2: =VLOOKUP($R2,Herbicide_Data!$A$1:$L$61,12) -> 16 | U2: =T2*($H2/43560) -> 1.1386593 | V2: =IF($G2 = ("Preemerge"),"MSM Turf 228-373") -> FALSE | W2: =VLOOKUP($V2,Herbicide_Data!$A$1:$L$17,9) -> #N/A | X2: =VLOOKUP($V2,Herbicide_Data!$A$1:$L$17,12) -> #N/A | Y2: =X2*($H2/43560) -> #N/A | AH2: =IF($G2 = ("Preemerge"),"Surfactant") -> FALSE | AI2: =VLOOKUP($AH2,Herbicide_Data!$A$1:$L$17,12) -> #N/A | AJ2: =AI2*($H2/43560) -> #N/A
A3: Dot Stuart | B3: 45591 | C3: 0.54166667 | D3: =C3+0.0208333 -> 0.56249997 | E3: Matthew Stowers | F3: =IFERROR(VLOOKUP(E3,Data!A$2:B$5,2,TRUE), "") -> 48160 | G3: Fall (pre/post emerge) | H3: =IFERROR(VLOOKUP(A3,Customer_Data!$A$1:$P$114,8,TRUE),"") -> 1800 | J3: =IF($G3=("Fall (pre/post emerge)"),"Princep Liquid (100-526)", IF($G3=("Fertilize"),"Harrell's 34-0-5",IF($G3=("Spot Treat"),"Outrider (59639-223)",""))) -> Princep Liquid (100-526) | K3: =(VLOOKUP($J3,Herbicide_Data!$A$1:$L$61,9,TRUE)) -> Simazine | L3: =VLOOKUP($J3,Herbicide_Data!$A$1:$L$61,12,TRUE) -> 32 | M3: =L3*(H3/43560) -> 1.322314 | N3: =IF($G3=("Fall (pre/post emerge)"),"Triplet SF (3-Way) 228-312",IF($G3=("Spring Preemerge (Jan)"),"Triplet SF (3-Way) 228-312",IF($G3=("Spring Preemerge (Apr)"),"Triplet SF (3-Way) 228-312",""))) -> Triplet SF (3-Way) 228-312 | O3: =VLOOKUP($N3,Herbicide_Data!$A$1:$L$61,9) -> 2,4-D, dimethylamine salt; Dicamba, dimethylamine salt;Mecoprop-p (MCPP-p), dimethylamine salt | P3: =VLOOKUP($N3,Herbicide_Data!$A$1:$L$61,12) -> 24 | Q3: =P3*($H3/43560) -> 0.99173554 | R3: =IF($G3=("Fall (pre/post emerge)"),"Resolute 4Fl (100-1139)",IF($G3=("Spring Preemerge (Jan)"),"Resolute 4Fl (100-1139)",IF($G3=("Spring Preemerge (Apr)"),"Certinty Turf 59639-226",""))) -> Resolute 4Fl (100-1139) | S3: =VLOOKUP($R3,Herbicide_Data!$A$1:$L$61,9) -> Prodiamine | T3: =VLOOKUP($R3,Herbicide_Data!$A$1:$L$61,12) -> 16 | U3: =T3*($H3/43560) -> 0.66115702 | V3: =IF($G3 = ("Preemerge"),"MSM Turf 228-373") -> FALSE | W3: =VLOOKUP($V3,Herbicide_Data!$A$1:$L$17,9) -> #N/A | X3: =VLOOKUP($V3,Herbicide_Data!$A$1:$L$17,12) -> #N/A | Y3: =X3*($H3/43560) -> #N/A | AH3: =IF($G3 = ("Preemerge"),"Surfactant") -> FALSE | AI3: =VLOOKUP($AH3,Herbicide_Data!$A$1:$L$17,12) -> #N/A | AJ3: =AI3*($H3/43560) -> #N/A
A4: Matt Runner | B4: 45591 | C4: 0.58333333 | D4: =C4+0.0208333 -> 0.60416663 | E4: Matthew Stowers | F4: =IFERROR(VLOOKUP(E4,Data!A$2:B$5,2,TRUE), "") -> 48160 | G4: Fall (pre/post emerge) | H4: =IFERROR(VLOOKUP(A4,Customer_Data!$A$1:$P$114,8,TRUE),"") -> 2000 | J4: =IF($G4=("Fall (pre/post emerge)"),"Princep Liquid (100-526)", IF($G4=("Fertilize"),"Harrell's 34-0-5",IF($G4=("Spot Treat"),"Outrider (59639-223)",""))) -> Princep Liquid (100-526) | K4: =(VLOOKUP($J4,Herbicide_Data!$A$1:$L$61,9,TRUE)) -> Simazine | L4: =VLOOKUP($J4,Herbicide_Data!$A$1:$L$61,12,TRUE) -> 32 | M4: =L4*(H4/43560) -> 1.4692378 | N4: =IF($G4=("Fall (pre/post emerge)"),"Triplet SF (3-Way) 228-312",IF($G4=("Spring Preemerge (Jan)"),"Triplet SF (3-Way) 228-312",IF($G4=("Spring Preemerge (Apr)"),"Triplet SF (3-Way) 228-312",""))) -> Triplet SF (3-Way) 228-312 | O4: =VLOOKUP($N4,Herbicide_Data!$A$1:$L$61,9) -> 2,4-D, dimethylamine salt; Dicamba, dimethylamine salt;Mecoprop-p (MCPP-p), dimethylamine salt | P4: =VLOOKUP($N4,Herbicide_Data!$A$1:$L$61,12) -> 24 | Q4: =P4*($H4/43560) -> 1.1019284 | R4: =IF($G4=("Fall (pre/post emerge)"),"Resolute 4Fl (100-1139)",IF($G4=("Spring Preemerge (Jan)"),"Resolute 4Fl (100-1139)",IF($G4=("Spring Preemerge (Apr)"),"Certinty Turf 59639-226",""))) -> Resolute 4Fl (100-1139) | S4: =VLOOKUP($R4,Herbicide_Data!$A$1:$L$61,9) -> Prodiamine | T4: =VLOOKUP($R4,Herbicide_Data!$A$1:$L$61,12) -> 16 | U4: =T4*($H4/43560) -> 0.73461892 | V4: =IF($G4 = ("Preemerge"),"MSM Turf 228-373") -> FALSE | W4: =VLOOKUP($V4,Herbicide_Data!$A$1:$L$17,9) -> #N/A | X4: =VLOOKUP($V4,Herbicide_Data!$A$1:$L$17,12) -> #N/A | Y4: =X4*($H4/43560) -> #N/A | AH4: =IF($G4 = ("Preemerge"),"Surfactant") -> FALSE | AI4: =VLOOKUP($AH4,Herbicide_Data!$A$1:$L$17,12) -> #N/A | AJ4: =AI4*($H4/43560) -> #N/A
A5: Luther Stowers | B5: 45591 | C5: 0.60416667 | D5: =C5+0.0208333 -> 0.62499997 | E5: Luther Stowers | F5: =IFERROR(VLOOKUP(E5,Data!A$2:B$5,2,TRUE), "") -> 48182 | G5: Fall (pre/post emerge) | H5: =IFERROR(VLOOKUP(A5,Customer_Data!$A$1:$P$114,8,TRUE),"") -> 5361 | J5: =IF($G5=("Fall (pre/post emerge)"),"Princep Liquid (100-526)", IF($G5=("Fertilize"),"Harrell's 34-0-5",IF($G5=("Spot Treat"),"Outrider (59639-223)",""))) -> Princep Liquid (100-526) | K5: =(VLOOKUP($J5,Herbicide_Data!$A$1:$L$61,9,TRUE)) -> Simazine | L5: =VLOOKUP($J5,Herbicide_Data!$A$1:$L$61,12,TRUE) -> 32 | M5: =L5*(H5/43560) -> 3.938292 | N5: =IF($G5=("Fall (pre/post emerge)"),"Triplet SF (3-Way) 228-312",IF($G5=("Spring Preemerge (Jan)"),"Triplet SF (3-Way) 228-312",IF($G5=("Spring Preemerge (Apr)"),"Triplet SF (3-Way) 228-312",""))) -> Triplet SF (3-Way) 228-312 | O5: =VLOOKUP($N5,Herbicide_Data!$A$1:$L$61,9) -> 2,4-D, dimethylamine salt; Dicamba, dimethylamine salt;Mecoprop-p (MCPP-p), dimethylamine salt | P5: =VLOOKUP($N5,Herbicide_Data!$A$1:$L$61,12) -> 24 | Q5: =P5*($H5/43560) -> 2.953719 | R5: =IF($G5=("Fall (pre/post emerge)"),"Resolute 4Fl (100-1139)",IF($G5=("Spring Preemerge (Jan)"),"Resolute 4Fl (100-1139)",IF($G5=("Spring Preemerge (Apr)"),"Certinty Turf 59639-226",""))) -> Resolute 4Fl (100-1139) | S5: =VLOOKUP($R5,Herbicide_Data!$A$1:$L$61,9) -> Prodiamine | T5: =VLOOKUP($R5,Herbicide_Data!$A$1:$L$61,12) -> 16 | U5: =T5*($H5/43560) -> 1.969146 | V5: =IF($G5 = ("Preemerge"),"MSM Turf 228-373") -> FALSE | W5: =VLOOKUP($V5,Herbicide_Data!$A$1:$L$17,9) -> #N/A | X5: =VLOOKUP($V5,Herbicide_Data!$A$1:$L$17,12) -> #N/A | Y5: =X5*($H5/43560) -> #N/A | AH5: =IF($G5 = ("Preemerge"),"Surfactant") -> FALSE | AI5: =VLOOKUP($AH5,Herbicide_Data!$A$1:$L$17,12) -> #N/A | AJ5: =AI5*($H5/43560) -> #N/A
A6: Bobby Fatheree | B6: 45592 | C6: 0.4375 | D6: =C6+0.0208333 -> 0.4583333 | E6: Matthew Stowers | F6: =IFERROR(VLOOKUP(E6,Data!A$2:B$5,2,TRUE), "") -> 48160 | G6: Fall (pre/post emerge) | H6: =IFERROR(VLOOKUP(A6,Customer_Data!$A$1:$P$114,8,TRUE),"") -> 8850 | J6: =IF($G6=("Fall (pre/post emerge)"),"Princep Liquid (100-526)", IF($G6=("Fertilize"),"Harrell's 34-0-5",IF($G6=("Spot Treat"),"Outrider (59639-223)",""))) -> Princep Liquid (100-526) | K6: =(VLOOKUP($J6,Herbicide_Data!$A$1:$L$61,9,TRUE)) -> Simazine | L6: =VLOOKUP($J6,Herbicide_Data!$A$1:$L$61,12,TRUE) -> 32 | M6: =L6*(H6/43560) -> 6.5013774 | N6: =IF($G6=("Fall (pre/post emerge)"),"Triplet SF (3-Way) 228-312",IF($G6=("Spring Preemerge (Jan)"),"Triplet SF (3-Way) 228-312",IF($G6=("Spring Preemerge (Apr)"),"Triplet SF (3-Way) 228-312",""))) -> Triplet SF (3-Way) 228-312 | O6: =VLOOKUP($N6,Herbicide_Data!$A$1:$L$61,9) -> 2,4-D, dimethylamine salt; Dicamba, dimethylamine salt;Mecoprop-p (MCPP-p), dimethylamine salt | P6: =VLOOKUP($N6,Herbicide_Data!$A$1:$L$61,12) -> 24 | Q6: =P6*($H6/43560) -> 4.8760331 | R6: =IF($G6=("Fall (pre/post emerge)"),"Resolute 4Fl (100-1139)",IF($G6=("Spring Preemerge (Jan)"),"Resolute 4Fl (100-1139)",IF($G6=("Spring Preemerge (Apr)"),"Certinty Turf 59639-226",""))) -> Resolute 4Fl (100-1139) | S6: =VLOOKUP($R6,Herbicide_Data!$A$1:$L$61,9) -> Prodiamine | T6: =VLOOKUP($R6,Herbicide_Data!$A$1:$L$61,12) -> 16 | U6: =T6*($H6/43560) -> 3.2506887 | V6: =IF($G6 = ("Preemerge"),"MSM Turf 228-373") -> FALSE | W6: =VLOOKUP($V6,Herbicide_Data!$A$1:$L$17,9) -> #N/A | X6: =VLOOKUP($V6,Herbicide_Data!$A$1:$L$17,12) -> #N/A | Y6: =X6*($H6/43560) -> #N/A | AH6: =IF($G6 = ("Preemerge"),"Surfactant") -> FALSE | AI6: =VLOOKUP($AH6,Herbicide_Data!$A$1:$L$17,12) -> #N/A | AJ6: =AI6*($H6/43560) -> #N/A
A7: Asa Barnes | B7: 45592 | C7: 0.45833333 | D7: =C7+0.0208333 -> 0.47916663 | E7: Matthew Stowers | F7: =IFERROR(VLOOKUP(E7,Data!A$2:B$5,2,TRUE), "") -> 48160 | G7: Fall (pre/post emerge) | H7: 6575 | J7: =IF($G7=("Fall (pre/post emerge)"),"Princep Liquid (100-526)", IF($G7=("Fertilize"),"Harrell's 34-0-5",IF($G7=("Spot Treat"),"Outrider (59639-223)",""))) -> Princep Liquid (100-526) | K7: =(VLOOKUP($J7,Herbicide_Data!$A$1:$L$61,9,TRUE)) -> Simazine | L7: =VLOOKUP($J7,Herbicide_Data!$A$1:$L$61,12,TRUE) -> 32 | M7: =L7*(H7/43560) -> 4.8301194 | N7: =IF($G7=("Fall (pre/post emerge)"),"Triplet SF (3-Way) 228-312",IF($G7=("Spring Preemerge (Jan)"),"Triplet SF (3-Way) 228-312",IF($G7=("Spring Preemerge (Apr)"),"Triplet SF (3-Way) 228-312",""))) -> Triplet SF (3-Way) 228-312 | O7: =VLOOKUP($N7,Herbicide_Data!$A$1:$L$61,9) -> 2,4-D, dimethylamine salt; Dicamba, dimethylamine salt;Mecoprop-p (MCPP-p), dimethylamine salt | P7: =VLOOKUP($N7,Herbicide_Data!$A$1:$L$61,12) -> 24 | Q7: =P7*($H7/43560) -> 3.6225895 | R7: =IF($G7=("Fall (pre/post emerge)"),"Resolute 4Fl (100-1139)",IF($G7=("Spring Preemerge (Jan)"),"Resolute 4Fl (100-1139)",IF($G7=("Spring Preemerge (Apr)"),"Certinty Turf 59639-226",""))) -> Resolute 4Fl (100-1139) | S7: =VLOOKUP($R7,Herbicide_Data!$A$1:$L$61,9) -> Prodiamine | T7: =VLOOKUP($R7,Herbicide_Data!$A$1:$L$61,12) -> 16 | U7: =T7*($H7/43560) -> 2.4150597 | V7: =IF($G7 = ("Preemerge"),"MSM Turf 228-373") -> FALSE | W7: =VLOOKUP($V7,Herbicide_Data!$A$1:$L$17,9) -> #N/A | X7: =VLOOKUP($V7,Herbicide_Data!$A$1:$L$17,12) -> #N/A | Y7: =X7*($H7/43560) -> #N/A | AH7: =IF($G7 = ("Preemerge"),"Surfactant") -> FALSE | AI7: =VLOOKUP($AH7,Herbicide_Data!$A$1:$L$17,12) -> #N/A | AJ7: =AI7*($H7/43560) -> #N/A
A8: David Fatheree | B8: 45592 | C8: 0.47916667 | D8: =C8+0.0208333 -> 0.49999997 | E8: Matthew Stowers | F8: =IFERROR(VLOOKUP(E8,Data!A$2:B$5,2,TRUE), "") -> 48160 | G8: Fall (pre/post emerge) | H8: =IFERROR(VLOOKUP(A8,Customer_Data!$A$1:$P$114,8,TRUE),"") -> 8910 | J8: =IF($G8=("Fall (pre/post emerge)"),"Princep Liquid (100-526)", IF($G8=("Fertilize"),"Harrell's 34-0-5",IF($G8=("Spot Treat"),"Outrider (59639-223)",""))) -> Princep Liquid (100-526) | K8: =(VLOOKUP($J8,Herbicide_Data!$A$1:$L$61,9,TRUE)) -> Simazine | L8: =VLOOKUP($J8,Herbicide_Data!$A$1:$L$61,12,TRUE) -> 32 | M8: =L8*(H8/43560) -> 6.5454545 | N8: =IF($G8=("Fall (pre/post emerge)"),"Triplet SF (3-Way) 228-312",IF($G8=("Spring Preemerge (Jan)"),"Triplet SF (3-Way) 228-312",IF($G8=("Spring Preemerge (Apr)"),"Triplet SF (3-Way) 228-312",""))) -> Triplet SF (3-Way) 228-312 | O8: =VLOOKUP($N8,Herbicide_Data!$A$1:$L$61,9) -> 2,4-D, dimethylamine salt; Dicamba, dimethylamine salt;Mecoprop-p (MCPP-p), dimethylamine salt | P8: =VLOOKUP($N8,Herbicide_Data!$A$1:$L$61,12) -> 24 | Q8: =P8*($H8/43560) -> 4.9090909 | R8: =IF($G8=("Fall (pre/post emerge)"),"Resolute 4Fl (100-1139)",IF($G8=("Spring Preemerge (Jan)"),"Resolute 4Fl (100-1139)",IF($G8=("Spring Preemerge (Apr)"),"Certinty Turf 59639-226",""))) -> Resolute 4Fl (100-1139) | S8: =VLOOKUP($R8,Herbicide_Data!$A$1:$L$61,9) -> Prodiamine | T8: =VLOOKUP($R8,Herbicide_Data!$A$1:$L$61,12) -> 16 | U8: =T8*($H8/43560) -> 3.2727273 | V8: =IF($G8 = ("Preemerge"),"MSM Turf 228-373") -> FALSE | W8: =VLOOKUP($V8,Herbicide_Data!$A$1:$L$17,9) -> #N/A | X8: =VLOOKUP($V8,Herbicide_Data!$A$1:$L$17,12) -> #N/A | Y8: =X8*($H8/43560) -> #N/A | AH8: =IF($G8 = ("Preemerge"),"Surfactant") -> FALSE | AI8: =VLOOKUP($AH8,Herbicide_Data!$A$1:$L$17,12) -> #N/A | AJ8: =AI8*($H8/43560) -> #N/A
A9: Matt Stowers | B9: 45592 | C9: 0.58333333 | D9: =C9+0.0208333 -> 0.60416663 | E9: Matthew Stowers | F9: =IFERROR(VLOOKUP(E9,Data!A$2:B$5,2,TRUE), "") -> 48160 | G9: Fall (pre/post emerge) | H9: =IFERROR(VLOOKUP(A9,Customer_Data!$A$1:$P$114,8,TRUE),"") -> 6568 | J9: =IF($G9=("Fall (pre/post emerge)"),"Princep Liquid (100-526)", IF($G9=("Fertilize"),"Harrell's 34-0-5",IF($G9=("Spot Treat"),"Outrider (59639-223)",""))) -> Princep Liquid (100-526) | K9: =(VLOOKUP($J9,Herbicide_Data!$A$1:$L$61,9,TRUE)) -> Simazine | L9: =VLOOKUP($J9,Herbicide_Data!$A$1:$L$61,12,TRUE) -> 32 | M9: =L9*(H9/43560) -> 4.824977 | N9: =IF($G9=("Fall (pre/post emerge)"),"Triplet SF (3-Way) 228-312",IF($G9=("Spring Preemerge (Jan)"),"Triplet SF (3-Way) 228-312",IF($G9=("Spring Preemerge (Apr)"),"Triplet SF (3-Way) 228-312",""))) -> Triplet SF (3-Way) 228-312 | O9: =VLOOKUP($N9,Herbicide_Data!$A$1:$L$61,9) -> 2,4-D, dimethylamine salt; Dicamba, dimethylamine salt;Mecoprop-p (MCPP-p), dimethylamine salt | P9: =VLOOKUP($N9,Herbicide_Data!$A$1:$L$61,12) -> 24 | Q9: =P9*($H9/43560) -> 3.6187328 | R9: =IF($G9=("Fall (pre/post emerge)"),"Resolute 4Fl (100-1139)",IF($G9=("Spring Preemerge (Jan)"),"Resolute 4Fl (100-1139)",IF($G9=("Spring Preemerge (Apr)"),"Certinty Turf 59639-226",""))) -> Resolute 4Fl (100-1139) | S9: =VLOOKUP($R9,Herbicide_Data!$A$1:$L$61,9) -> Prodiamine | T9: =VLOOKUP($R9,Herbicide_Data!$A$1:$L$61,12) -> 16 | U9: =T9*($H9/43560) -> 2.4124885 | V9: =IF($G9 = ("Preemerge"),"MSM Turf 228-373") -> FALSE | W9: =VLOOKUP($V9,Herbicide_Data!$A$1:$L$17,9) -> #N/A | X9: =VLOOKUP($V9,Herbicide_Data!$A$1:$L$17,12) -> #N/A | Y9: =X9*($H9/43560) -> #N/A | AH9: =IF($G9 = ("Preemerge"),"Surfactant") -> FALSE | AI9: =VLOOKUP($AH9,Herbicide_Data!$A$1:$L$17,12) -> #N/A | AJ9: =AI9*($H9/43560) -> #N/A
A10: Luther Holmes | B10: 45604 | C10: 0.58333333 | D10: =C10+0.0208333 -> 0.60416663 | E10: Luther Stowers | F10: =IFERROR(VLOOKUP(E10,Data!A$2:B$5,2,TRUE), "") -> 48182 | G10: Fall (pre/post emerge) | H10: =IFERROR(VLOOKUP(A10,Customer_Data!$A$1:$P$114,8,TRUE),"") -> 3687 | J10: =IF($G10=("Fall (pre/post emerge)"),"Princep Liquid (100-526)", IF($G10=("Fertilize"),"Harrell's 34-0-5",IF($G10=("Spot Treat"),"Outrider (59639-223)",""))) -> Princep Liquid (100-526) | K10: =(VLOOKUP($J10,Herbicide_Data!$A$1:$L$61,9,TRUE)) -> Simazine | L10: =VLOOKUP($J10,Herbicide_Data!$A$1:$L$61,12,TRUE) -> 32 | M10: =L10*(H10/43560) -> 2.7085399 | N10: =IF($G10=("Fall (pre/post emerge)"),"Triplet SF (3-Way) 228-312",IF($G10=("Spring Preemerge (Jan)"),"Triplet SF (3-Way) 228-312",IF($G10=("Spring Preemerge (Apr)"),"Triplet SF (3-Way) 228-312",""))) -> Triplet SF (3-Way) 228-312 | O10: =VLOOKUP($N10,Herbicide_Data!$A$1:$L$61,9) -> 2,4-D, dimethylamine salt; Dicamba, dimethylamine salt;Mecoprop-p (MCPP-p), dimethylamine salt | P10: =VLOOKUP($N10,Herbicide_Data!$A$1:$L$61,12) -> 24 | Q10: =P10*($H10/43560) -> 2.031405 | R10: =IF($G10=("Fall (pre/post emerge)"),"Resolute 4Fl (100-1139)",IF($G10=("Spring Preemerge (Jan)"),"Resolute 4Fl (100-1139)",IF($G10=("Spring Preemerge (Apr)"),"Certinty Turf 59639-226",""))) -> Resolute 4Fl (100-1139) | S10: =VLOOKUP($R10,Herbicide_Data!$A$1:$L$61,9) -> Prodiamine | T10: =VLOOKUP($R10,Herbicide_Data!$A$1:$L$61,12) -> 16 | U10: =T10*($H10/43560) -> 1.35427 | V10: =IF($G10 = ("Preemerge"),"MSM Turf 228-373") -> FALSE | W10: =VLOOKUP($V10,Herbicide_Data!$A$1:$L$17,9) -> #N/A | X10: =VLOOKUP($V10,Herbicide_Data!$A$1:$L$17,12) -> #N/A | Y10: =X10*($H10/43560) -> #N/A | AH10: =IF($G10 = ("Preemerge"),"Surfactant") -> FALSE | AI10: =VLOOKUP($AH10,Herbicide_Data!$A$1:$L$17,12) -> #N/A | AJ10: =AI10*($H10/43560) -> #N/A
A11: David Fatheree | B11: 45710 | C11: 0.41666667 | D11: =C11+0.0208333 -> 0.43749997 | E11: Matthew Stowers | F11: =IFERROR(VLOOKUP(E11,Data!A$2:B$5,2,TRUE), "") -> 48160 | G11: Spring Preemerge (Jan) | H11: =IFERROR(VLOOKUP(A11,Customer_Data!$A$1:$P$114,8,TRUE),"") -> 8910 | J11: =IF($G11=("Fall (pre/post emerge)"),"Princep Liquid (100-526)", IF($G11=("Fertilize"),"Harrell's 34-0-5",IF($G11=("Spot Treat"),"Outrider (59639-223)",""))) | K11: =(VLOOKUP($J11,Herbicide_Data!$A$1:$L$61,9,TRUE)) -> #N/A | L11: =VLOOKUP($J11,Herbicide_Data!$A$1:$L$61,12,TRUE) -> #N/A | M11: =L11*(H11/43560) -> #N/A | N11: =IF($G11=("Fall (pre/post emerge)"),"Triplet SF (3-Way) 228-312",IF($G11=("Spring Preemerge (Jan)"),"Triplet SF (3-Way) 228-312",IF($G11=("Spring Preemerge (Apr)"),"Triplet SF (3-Way) 228-312",""))) -> Triplet SF (3-Way) 228-312 | O11: =VLOOKUP($N11,Herbicide_Data!$A$1:$L$61,9) -> 2,4-D, dimethylamine salt; Dicamba, dimethylamine salt;Mecoprop-p (MCPP-p), dimethylamine salt | P11: =VLOOKUP($N11,Herbicide_Data!$A$1:$P$61,13) -> 24 | Q11: =P11*($H11/43560) -> 4.9090909 | R11: =IF($G11=("Fall (pre/post emerge)"),"Resolute 4Fl (100-1139)",IF($G11=("Spring Preemerge (Jan)"),"Resolute 4Fl (100-1139)",IF($G11=("Spring Preemerge (Apr)"),"Certinty Turf 59639-226",""))) -> Resolute 4Fl (100-1139) | S11: =VLOOKUP($R11,Herbicide_Data!$A$1:$L$61,9) -> Prodiamine | T11: =VLOOKUP($R11,Herbicide_Data!$A$1:$Q$61,13) -> 16 | U11: =T11*($H11/43560) -> 3.2727273 | V11: =IF($G11 = ("Preemerge"),"MSM Turf 228-373") -> FALSE | W11: =VLOOKUP($V11,Herbicide_Data!$A$1:$L$17,9) -> #N/A | X11: =VLOOKUP($V11,Herbicide_Data!$A$1:$L$17,12) -> #N/A | Y11: =X11*($H11/43560) -> #N/A | AH11: =IF($G11 = ("Spring Preemerge (Jan)"),"Surfactant") -> Surfactant | AI11: =VLOOKUP($AH11,Herbicide_Data!$A$1:$Q$61,13) -> 12.8 | AJ11: =AI11*($H11/43560) -> 2.6181818
A12: Riley Cooper | B12: 45710 | C12: 0.4375 | D12: =C12+0.0208333 -> 0.4583333 | E12: Matthew Stowers | F12: =IFERROR(VLOOKUP(E12,Data!A$2:B$5,2,TRUE), "") -> 48160 | G12: Spring Preemerge (Jan) | H12: =IFERROR(VLOOKUP(A12,Customer_Data!$A$1:$P$114,8,TRUE),"") -> 4150 | J12: =IF($G12=("Fall (pre/post emerge)"),"Princep Liquid (100-526)", IF($G12=("Fertilize"),"Harrell's 34-0-5",IF($G12=("Spot Treat"),"Outrider (59639-223)",""))) | K12: =(VLOOKUP($J12,Herbicide_Data!$A$1:$L$61,9,TRUE)) -> #N/A | L12: =VLOOKUP($J12,Herbicide_Data!$A$1:$L$61,12,TRUE) -> #N/A | M12: =L12*(H12/43560) -> #N/A | N12: =IF($G12=("Fall (pre/post emerge)"),"Triplet SF (3-Way) 228-312",IF($G12=("Spring Preemerge (Jan)"),"Triplet SF (3-Way) 228-312",IF($G12=("Spring Preemerge (Apr)"),"Triplet SF (3-Way) 228-312",""))) -> Triplet SF (3-Way) 228-312 | O12: =VLOOKUP($N12,Herbicide_Data!$A$1:$L$61,9) -> 2,4-D, dimethylamine salt; Dicamba, dimethylamine salt;Mecoprop-p (MCPP-p), dimethylamine salt | P12: =VLOOKUP($N12,Herbicide_Data!$A$1:$P$61,13) -> 24 | Q12: =P12*($H12/43560) -> 2.2865014 | R12: =IF($G12=("Fall (pre/post emerge)"),"Resolute 4Fl (100-1139)",IF($G12=("Spring Preemerge (Jan)"),"Resolute 4Fl (100-1139)",IF($G12=("Spring Preemerge (Apr)"),"Certinty Turf 59639-226",""))) -> Resolute 4Fl (100-1139) | S12: =VLOOKUP($R12,Herbicide_Data!$A$1:$L$61,9) -> Prodiamine | T12: =VLOOKUP($R12,Herbicide_Data!$A$1:$Q$61,13) -> 16 | U12: =T12*($H12/43560) -> 1.5243343 | V12: =IF($G12 = ("Preemerge"),"MSM Turf 228-373") -> FALSE | W12: =VLOOKUP($V12,Herbicide_Data!$A$1:$L$17,9) -> #N/A | X12: =VLOOKUP($V12,Herbicide_Data!$A$1:$L$17,12) -> #N/A | Y12: =X12*($H12/43560) -> #N/A | AH12: =IF($G12 = ("Spring Preemerge (Jan)"),"Surfactant") -> Surfactant | AI12: =VLOOKUP($AH12,Herbicide_Data!$A$1:$Q$61,13) -> 12.8 | AJ12: =AI12*($H12/43560) -> 1.2194674
A13: Thomas Wilson | B13: 45710 | C13: 0.45833333 | D13: =C13+0.0208333 -> 0.47916663 | E13: Matthew Stowers | F13: =IFERROR(VLOOKUP(E13,Data!A$2:B$5,2,TRUE), "") -> 48160 | G13: Spring Preemerge (Jan) | H13: =IFERROR(VLOOKUP(A13,Customer_Data!$A$1:$P$114,8,TRUE),"") -> 3875 | J13: =IF($G13=("Fall (pre/post emerge)"),"Princep Liquid (100-526)", IF($G13=("Fertilize"),"Harrell's 34-0-5",IF($G13=("Spot Treat"),"Outrider (59639-223)",""))) | K13: =(VLOOKUP($J13,Herbicide_Data!$A$1:$L$61,9,TRUE)) -> #N/A | L13: =VLOOKUP($J13,Herbicide_Data!$A$1:$L$61,12,TRUE) -> #N/A | M13: =L13*(H13/43560) -> #N/A | N13: =IF($G13=("Fall (pre/post emerge)"),"Triplet SF (3-Way) 228-312",IF($G13=("Spring Preemerge (Jan)"),"Triplet SF (3-Way) 228-312",IF($G13=("Spring Preemerge (Apr)"),"Triplet SF (3-Way) 228-312",""))) -> Triplet SF (3-Way) 228-312 | O13: =VLOOKUP($N13,Herbicide_Data!$A$1:$L$61,9) -> 2,4-D, dimethylamine salt; Dicamba, dimethylamine salt;Mecoprop-p (MCPP-p), dimethylamine salt | P13: =VLOOKUP($N13,Herbicide_Data!$A$1:$P$61,13) -> 24 | Q13: =P13*($H13/43560) -> 2.1349862 | R13: =IF($G13=("Fall (pre/post emerge)"),"Resolute 4Fl (100-1139)",IF($G13=("Spring Preemerge (Jan)"),"Resolute 4Fl (100-1139)",IF($G13=("Spring Preemerge (Apr)"),"Certinty Turf 59639-226",""))) -> Resolute 4Fl (100-1139) | S13: =VLOOKUP($R13,Herbicide_Data!$A$1:$L$61,9) -> Prodiamine | T13: =VLOOKUP($R13,Herbicide_Data!$A$1:$Q$61,13) -> 16 | U13: =T13*($H13/43560) -> 1.4233242 | V13: =IF($G13 = ("Preemerge"),"MSM Turf 228-373") -> FALSE | W13: =VLOOKUP($V13,Herbicide_Data!$A$1:$L$17,9) -> #N/A | X13: =VLOOKUP($V13,Herbicide_Data!$A$1:$L$17,12) -> #N/A | Y13: =X13*($H13/43560) -> #N/A | AH13: =IF($G13 = ("Spring Preemerge (Jan)"),"Surfactant") -> Surfactant | AI13: =VLOOKUP($AH13,Herbicide_Data!$A$1:$Q$61,13) -> 12.8 | AJ13: =AI13*($H13/43560) -> 1.1386593
A14: Max Miller | B14: 45710 | C14: 0.5 | D14: =C14+0.0208333 -> 0.5208333 | E14: Matthew Stowers | F14: =IFERROR(VLOOKUP(E14,Data!A$2:B$5,2,TRUE), "") -> 48160 | G14: Spring Preemerge (Jan) | H14: =IFERROR(VLOOKUP(A14,Customer_Data!$A$1:$P$114,8,TRUE),"") -> 3100 | J14: =IF($G14=("Fall (pre/post emerge)"),"Princep Liquid (100-526)", IF($G14=("Fertilize"),"Harrell's 34-0-5",IF($G14=("Spot Treat"),"Outrider (59639-223)",""))) | K14: =(VLOOKUP($J14,Herbicide_Data!$A$1:$L$61,9,TRUE)) -> #N/A | L14: =VLOOKUP($J14,Herbicide_Data!$A$1:$L$61,12,TRUE) -> #N/A | M14: =L14*(H14/43560) -> #N/A | N14: =IF($G14=("Fall (pre/post emerge)"),"Triplet SF (3-Way) 228-312",IF($G14=("Spring Preemerge (Jan)"),"Triplet SF (3-Way) 228-312",IF($G14=("Spring Preemerge (Apr)"),"Triplet SF (3-Way) 228-312",""))) -> Triplet SF (3-Way) 228-312 | O14: =VLOOKUP($N14,Herbicide_Data!$A$1:$L$61,9) -> 2,4-D, dimethylamine salt; Dicamba, dimethylamine salt;Mecoprop-p (MCPP-p), dimethylamine salt | P14: =VLOOKUP($N14,Herbicide_Data!$A$1:$P$61,13) -> 24 | Q14: =P14*($H14/43560) -> 1.707989 | R14: =IF($G14=("Fall (pre/post emerge)"),"Resolute 4Fl (100-1139)",IF($G14=("Spring Preemerge (Jan)"),"Resolute 4Fl (100-1139)",IF($G14=("Spring Preemerge (Apr)"),"Certinty Turf 59639-226",""))) -> Resolute 4Fl (100-1139) | S14: =VLOOKUP($R14,Herbicide_Data!$A$1:$L$61,9) -> Prodiamine | T14: =VLOOKUP($R14,Herbicide_Data!$A$1:$Q$61,13) -> 16 | U14: =T14*($H14/43560) -> 1.1386593 | V14: =IF($G14 = ("Preemerge"),"MSM Turf 228-373") -> FALSE | W14: =VLOOKUP($V14,Herbicide_Data!$A$1:$L$17,9) -> #N/A | X14: =VLOOKUP($V14,Herbicide_Data!$A$1:$L$17,12) -> #N/A | Y14: =X14*($H14/43560) -> #N/A | AH14: =IF($G14 = ("Spring Preemerge (Jan)"),"Surfactant") -> Surfactant | AI14: =VLOOKUP($AH14,Herbicide_Data!$A$1:$Q$61,13) -> 12.8 | AJ14: =AI14*($H14/43560) -> 0.91092746
A15: Luther Holmes | B15: 45710 | C15: 0.54166667 | D15: =C15+0.0208333 -> 0.56249997 | E15: Luther Stowers | F15: =IFERROR(VLOOKUP(E15,Data!A$2:B$5,2,TRUE), "") -> 48182 | G15: Spring Preemerge (Jan) | H15: =IFERROR(VLOOKUP(A15,Customer_Data!$A$1:$P$114,8,TRUE),"") -> 3687 | J15: =IF($G15=("Fall (pre/post emerge)"),"Princep Liquid (100-526)", IF($G15=("Fertilize"),"Harrell's 34-0-5",IF($G15=("Spot Treat"),"Outrider (59639-223)",""))) | K15: =(VLOOKUP($J15,Herbicide_Data!$A$1:$L$61,9,TRUE)) -> #N/A | L15: =VLOOKUP($J15,Herbicide_Data!$A$1:$L$61,12,TRUE) -> #N/A | M15: =L15*(H15/43560) -> #N/A | N15: =IF($G15=("Fall (pre/post emerge)"),"Triplet SF (3-Way) 228-312",IF($G15=("Spring Preemerge (Jan)"),"Triplet SF (3-Way) 228-312",IF($G15=("Spring Preemerge (Apr)"),"Triplet SF (3-Way) 228-312",""))) -> Triplet SF (3-Way) 228-312 | O15: =VLOOKUP($N15,Herbicide_Data!$A$1:$L$61,9) -> 2,4-D, dimethylamine salt; Dicamba, dimethylamine salt;Mecoprop-p (MCPP-p), dimethylamine salt | P15: =VLOOKUP($N15,Herbicide_Data!$A$1:$P$61,13) -> 24 | Q15: =P15*($H15/43560) -> 2.031405 | R15: =IF($G15=("Fall (pre/post emerge)"),"Resolute 4Fl (100-1139)",IF($G15=("Spring Preemerge (Jan)"),"Resolute 4Fl (100-1139)",IF($G15=("Spring Preemerge (Apr)"),"Certinty Turf 59639-226",""))) -> Resolute 4Fl (100-1139) | S15: =VLOOKUP($R15,Herbicide_Data!$A$1:$L$61,9) -> Prodiamine | T15: =VLOOKUP($R15,Herbicide_Data!$A$1:$Q$61,13) -> 16 | U15: =T15*($H15/43560) -> 1.35427 | V15: =IF($G15 = ("Preemerge"),"MSM Turf 228-373") -> FALSE | W15: =VLOOKUP($V15,Herbicide_Data!$A$1:$L$17,9) -> #N/A | X15: =VLOOKUP($V15,Herbicide_Data!$A$1:$L$17,12) -> #N/A | Y15: =X15*($H15/43560) -> #N/A | AH15: =IF($G15 = ("Spring Preemerge (Jan)"),"Surfactant") -> Surfactant | AI15: =VLOOKUP($AH15,Herbicide_Data!$A$1:$Q$61,13) -> 12.8 | AJ15: =AI15*($H15/43560) -> 1.083416
A16: Bo Whatley | B16: 45710 | C16: 0.5625 | D16: =C16+0.0208333 -> 0.5833333 | E16: Matthew Stowers | F16: =IFERROR(VLOOKUP(E16,Data!A$2:B$5,2,TRUE), "") -> 48160 | G16: Spring Preemerge (Jan) | H16: =IFERROR(VLOOKUP(A16,Customer_Data!$A$1:$P$114,8,TRUE),"") -> 2750 | J16: =IF($G16=("Fall (pre/post emerge)"),"Princep Liquid (100-526)", IF($G16=("Fertilize"),"Harrell's 34-0-5",IF($G16=("Spot Treat"),"Outrider (59639-223)",""))) | K16: =(VLOOKUP($J16,Herbicide_Data!$A$1:$L$61,9,TRUE)) -> #N/A | L16: =VLOOKUP($J16,Herbicide_Data!$A$1:$L$61,12,TRUE) -> #N/A | M16: =L16*(H16/43560) -> #N/A | N16: =IF($G16=("Fall (pre/post emerge)"),"Triplet SF (3-Way) 228-312",IF($G16=("Spring Preemerge (Jan)"),"Triplet SF (3-Way) 228-312",IF($G16=("Spring Preemerge (Apr)"),"Triplet SF (3-Way) 228-312",""))) -> Triplet SF (3-Way) 228-312 | O16: =VLOOKUP($N16,Herbicide_Data!$A$1:$L$61,9) -> 2,4-D, dimethylamine salt; Dicamba, dimethylamine salt;Mecoprop-p (MCPP-p), dimethylamine salt | P16: =VLOOKUP($N16,Herbicide_Data!$A$1:$P$61,13) -> 24 | Q16: =P16*($H16/43560) -> 1.5151515 | R16: =IF($G16=("Fall (pre/post emerge)"),"Resolute 4Fl (100-1139)",IF($G16=("Spring Preemerge (Jan)"),"Resolute 4Fl (100-1139)",IF($G16=("Spring Preemerge (Apr)"),"Certinty Turf 59639-226",""))) -> Resolute 4Fl (100-1139) | S16: =VLOOKUP($R16,Herbicide_Data!$A$1:$L$61,9) -> Prodiamine | T16: =VLOOKUP($R16,Herbicide_Data!$A$1:$Q$61,13) -> 16 | U16: =T16*($H16/43560) -> 1.010101 | V16: =IF($G16 = ("Preemerge"),"MSM Turf 228-373") -> FALSE | W16: =VLOOKUP($V16,Herbicide_Data!$A$1:$L$17,9) -> #N/A | X16: =VLOOKUP($V16,Herbicide_Data!$A$1:$L$17,12) -> #N/A | Y16: =X16*($H16/43560) -> #N/A | AH16: =IF($G16 = ("Spring Preemerge (Jan)"),"Surfactant") -> Surfactant | AI16: =VLOOKUP($AH16,Herbicide_Data!$A$1:$Q$61,13) -> 12.8 | AJ16: =AI16*($H16/43560) -> 0.80808081
A17: Matt Stowers | B17: 45710 | C17: 0.5625 | D17: =C17+0.0208333 -> 0.5833333 | E17: Matthew Stowers | F17: =IFERROR(VLOOKUP(E17,Data!A$2:B$5,2,TRUE), "") -> 48160 | G17: Spring Preemerge (Jan) | H17: =IFERROR(VLOOKUP(A17,Customer_Data!$A$1:$P$114,8,TRUE),"") -> 6568 | J17: =IF($G17=("Fall (pre/post emerge)"),"Princep Liquid (100-526)", IF($G17=("Fertilize"),"Harrell's 34-0-5",IF($G17=("Spot Treat"),"Outrider (59639-223)",""))) | K17: =(VLOOKUP($J17,Herbicide_Data!$A$1:$L$61,9,TRUE)) -> #N/A | L17: =VLOOKUP($J17,Herbicide_Data!$A$1:$L$61,12,TRUE) -> #N/A | M17: =L17*(H17/43560) -> #N/A | N17: =IF($G17=("Fall (pre/post emerge)"),"Triplet SF (3-Way) 228-312",IF($G17=("Spring Preemerge (Jan)"),"Triplet SF (3-Way) 228-312",IF($G17=("Spring Preemerge (Apr)"),"Triplet SF (3-Way) 228-312",""))) -> Triplet SF (3-Way) 228-312 | O17: =VLOOKUP($N17,Herbicide_Data!$A$1:$L$61,9) -> 2,4-D, dimethylamine salt; Dicamba, dimethylamine salt;Mecoprop-p (MCPP-p), dimethylamine salt | P17: =VLOOKUP($N17,Herbicide_Data!$A$1:$P$61,13) -> 24 | Q17: =P17*($H17/43560) -> 3.6187328 | R17: =IF($G17=("Fall (pre/post emerge)"),"Resolute 4Fl (100-1139)",IF($G17=("Spring Preemerge (Jan)"),"Resolute 4Fl (100-1139)",IF($G17=("Spring Preemerge (Apr)"),"Certinty Turf 59639-226",""))) -> Resolute 4Fl (100-1139) | S17: =VLOOKUP($R17,Herbicide_Data!$A$1:$L$61,9) -> Prodiamine | T17: =VLOOKUP($R17,Herbicide_Data!$A$1:$Q$61,13) -> 16 | U17: =T17*($H17/43560) -> 2.4124885 | V17: =IF($G17 = ("Preemerge"),"MSM Turf 228-373") -> FALSE | W17: =VLOOKUP($V17,Herbicide_Data!$A$1:$L$17,9) -> #N/A | X17: =VLOOKUP($V17,Herbicide_Data!$A$1:$L$17,12) -> #N/A | Y17: =X17*($H17/43560) -> #N/A | AH17: =IF($G17 = ("Spring Preemerge (Jan)"),"Surfactant") -> Surfactant | AI17: =VLOOKUP($AH17,Herbicide_Data!$A$1:$Q$61,13) -> 12.8 | AJ17: =AI17*($H17/43560) -> 1.9299908
A18: Matt Runner | B18: 45710 | C18: 0.58333333 | D18: =C18+0.0208333 -> 0.60416663 | E18: Matthew Stowers | F18: =IFERROR(VLOOKUP(E18,Data!A$2:B$5,2,TRUE), "") -> 48160 | G18: Spring Preemerge (Jan) | H18: =IFERROR(VLOOKUP(A18,Customer_Data!$A$1:$P$114,8,TRUE),"") -> 2000 | J18: =IF($G18=("Fall (pre/post emerge)"),"Princep Liquid (100-526)", IF($G18=("Fertilize"),"Harrell's 34-0-5",IF($G18=("Spot Treat"),"Outrider (59639-223)",""))) | K18: =(VLOOKUP($J18,Herbicide_Data!$A$1:$L$61,9,TRUE)) -> #N/A | L18: =VLOOKUP($J18,Herbicide_Data!$A$1:$L$61,12,TRUE) -> #N/A | M18: =L18*(H18/43560) -> #N/A | N18: =IF($G18=("Fall (pre/post emerge)"),"Triplet SF (3-Way) 228-312",IF($G18=("Spring Preemerge (Jan)"),"Triplet SF (3-Way) 228-312",IF($G18=("Spring Preemerge (Apr)"),"Triplet SF (3-Way) 228-312",""))) -> Triplet SF (3-Way) 228-312 | O18: =VLOOKUP($N18,Herbicide_Data!$A$1:$L$61,9) -> 2,4-D, dimethylamine salt; Dicamba, dimethylamine salt;Mecoprop-p (MCPP-p), dimethylamine salt | P18: =VLOOKUP($N18,Herbicide_Data!$A$1:$P$61,13) -> 24 | Q18: =P18*($H18/43560) -> 1.1019284 | R18: =IF($G18=("Fall (pre/post emerge)"),"Resolute 4Fl (100-1139)",IF($G18=("Spring Preemerge (Jan)"),"Resolute 4Fl (100-1139)",IF($G18=("Spring Preemerge (Apr)"),"Certinty Turf 59639-226",""))) -> Resolute 4Fl (100-1139) | S18: =VLOOKUP($R18,Herbicide_Data!$A$1:$L$61,9) -> Prodiamine | T18: =VLOOKUP($R18,Herbicide_Data!$A$1:$Q$61,13) -> 16 | U18: =T18*($H18/43560) -> 0.73461892 | V18: =IF($G18 = ("Preemerge"),"MSM Turf 228-373") -> FALSE | W18: =VLOOKUP($V18,Herbicide_Data!$A$1:$L$17,9) -> #N/A | X18: =VLOOKUP($V18,Herbicide_Data!$A$1:$L$17,12) -> #N/A | Y18: =X18*($H18/43560) -> #N/A | AH18: =IF($G18 = ("Spring Preemerge (Jan)"),"Surfactant") -> Surfactant | AI18: =VLOOKUP($AH18,Herbicide_Data!$A$1:$Q$61,13) -> 12.8 | AJ18: =AI18*($H18/43560) -> 0.58769513
A19: Asa Barnes | B19: 45710 | C19: =IF(ISBLANK($A19),"",NOW()-TODAY()) -> 0.63285475 | D19: =C19+0.0208333 -> 0.65368805 | E19: Matthew Stowers | F19: =IFERROR(VLOOKUP(E19,Data!A$2:B$5,2,TRUE), "") -> 48160 | G19: Spring Preemerge (Jan) | H19: 6575 | J19: =IF($G19=("Fall (pre/post emerge)"),"Princep Liquid (100-526)", IF($G19=("Fertilize"),"Harrell's 34-0-5",IF($G19=("Spot Treat"),"Outrider (59639-223)",""))) | K19: =(VLOOKUP($J19,Herbicide_Data!$A$1:$L$61,9,TRUE)) -> #N/A | L19: =VLOOKUP($J19,Herbicide_Data!$A$1:$L$61,12,TRUE) -> #N/A | M19: =L19*(H19/43560) -> #N/A | N19: =IF($G19=("Fall (pre/post emerge)"),"Triplet SF (3-Way) 228-312",IF($G19=("Spring Preemerge (Jan)"),"Triplet SF (3-Way) 228-312",IF($G19=("Spring Preemerge (Apr)"),"Triplet SF (3-Way) 228-312",""))) -> Triplet SF (3-Way) 228-312 | O19: =VLOOKUP($N19,Herbicide_Data!$A$1:$L$61,9) -> 2,4-D, dimethylamine salt; Dicamba, dimethylamine salt;Mecoprop-p (MCPP-p), dimethylamine salt | P19: =VLOOKUP($N19,Herbicide_Data!$A$1:$P$61,13) -> 24 | Q19: =P19*($H19/43560) -> 3.6225895 | R19: =IF($G19=("Fall (pre/post emerge)"),"Resolute 4Fl (100-1139)",IF($G19=("Spring Preemerge (Jan)"),"Resolute 4Fl (100-1139)",IF($G19=("Spring Preemerge (Apr)"),"Certinty Turf 59639-226",""))) -> Resolute 4Fl (100-1139) | S19: =VLOOKUP($R19,Herbicide_Data!$A$1:$L$61,9) -> Prodiamine | T19: =VLOOKUP($R19,Herbicide_Data!$A$1:$Q$61,13) -> 16 | U19: =T19*($H19/43560) -> 2.4150597 | V19: =IF($G19 = ("Preemerge"),"MSM Turf 228-373") -> FALSE | W19: =VLOOKUP($V19,Herbicide_Data!$A$1:$L$17,9) -> #N/A | X19: =VLOOKUP($V19,Herbicide_Data!$A$1:$L$17,12) -> #N/A | Y19: =X19*($H19/43560) -> #N/A | AH19: =IF($G19 = ("Spring Preemerge (Jan)"),"Surfactant") -> Surfactant | AI19: =VLOOKUP($AH19,Herbicide_Data!$A$1:$Q$61,13) -> 12.8 | AJ19: =AI19*($H19/43560) -> 1.9320478
A20: Brandon Bergold | B20: 45710 | C20: 0.60416667 | D20: =C20+0.0208333 -> 0.62499997 | E20: Matthew Stowers | F20: =IFERROR(VLOOKUP(E20,Data!A$2:B$5,2,TRUE), "") -> 48160 | G20: Spring Preemerge (Jan) | H20: =IFERROR(VLOOKUP(A20,Customer_Data!$A$1:$P$114,8,TRUE),"") -> 5670 | J20: =IF($G20=("Fall (pre/post emerge)"),"Princep Liquid (100-526)", IF($G20=("Fertilize"),"Harrell's 34-0-5",IF($G20=("Spot Treat"),"Outrider (59639-223)",""))) | K20: =(VLOOKUP($J20,Herbicide_Data!$A$1:$L$61,9,TRUE)) -> #N/A | L20: =VLOOKUP($J20,Herbicide_Data!$A$1:$L$61,12,TRUE) -> #N/A | M20: =L20*(H20/43560) -> #N/A | N20: =IF($G20=("Fall (pre/post emerge)"),"Triplet SF (3-Way) 228-312",IF($G20=("Spring Preemerge (Jan)"),"Triplet SF (3-Way) 228-312",IF($G20=("Spring Preemerge (Apr)"),"Triplet SF (3-Way) 228-312",""))) -> Triplet SF (3-Way) 228-312 | O20: =VLOOKUP($N20,Herbicide_Data!$A$1:$L$61,9) -> 2,4-D, dimethylamine salt; Dicamba, dimethylamine salt;Mecoprop-p (MCPP-p), dimethylamine salt | P20: =VLOOKUP($N20,Herbicide_Data!$A$1:$P$61,13) -> 24 | Q20: =P20*($H20/43560) -> 3.1239669 | R20: =IF($G20=("Fall (pre/post emerge)"),"Resolute 4Fl (100-1139)",IF($G20=("Spring Preemerge (Jan)"),"Resolute 4Fl (100-1139)",IF($G20=("Spring Preemerge (Apr)"),"Certinty Turf 59639-226",""))) -> Resolute 4Fl (100-1139) | S20: =VLOOKUP($R20,Herbicide_Data!$A$1:$L$61,9) -> Prodiamine | T20: =VLOOKUP($R20,Herbicide_Data!$A$1:$Q$61,13) -> 16 | U20: =T20*($H20/43560) -> 2.0826446 | V20: =IF($G20 = ("Preemerge"),"MSM Turf 228-373") -> FALSE | W20: =VLOOKUP($V20,Herbicide_Data!$A$1:$L$17,9) -> #N/A | X20: =VLOOKUP($V20,Herbicide_Data!$A$1:$L$17,12) -> #N/A | Y20: =X20*($H20/43560) -> #N/A | AH20: =IF($G20 = ("Spring Preemerge (Jan)"),"Surfactant") -> Surfactant | AI20: =VLOOKUP($AH20,Herbicide_Data!$A$1:$Q$61,13) -> 12.8 | AJ20: =AI20*($H20/43560) -> 1.6661157
A21: Dot Stuart | B21: 45710 | C21: 0.625 | D21: =C21+0.0208333 -> 0.6458333 | E21: Matthew Stowers | F21: =IFERROR(VLOOKUP(E21,Data!A$2:B$5,2,TRUE), "") -> 48160 | G21: Spring Preemerge (Jan) | H21: =IFERROR(VLOOKUP(A21,Customer_Data!$A$1:$P$114,8,TRUE),"") -> 1800 | J21: =IF($G21=("Fall (pre/post emerge)"),"Princep Liquid (100-526)", IF($G21=("Fertilize"),"Harrell's 34-0-5",IF($G21=("Spot Treat"),"Outrider (59639-223)",""))) | K21: =(VLOOKUP($J21,Herbicide_Data!$A$1:$L$61,9,TRUE)) -> #N/A | L21: =VLOOKUP($J21,Herbicide_Data!$A$1:$L$61,12,TRUE) -> #N/A | M21: =L21*(H21/43560) -> #N/A | N21: =IF($G21=("Fall (pre/post emerge)"),"Triplet SF (3-Way) 228-312",IF($G21=("Spring Preemerge (Jan)"),"Triplet SF (3-Way) 228-312",IF($G21=("Spring Preemerge (Apr)"),"Triplet SF (3-Way) 228-312",""))) -> Triplet SF (3-Way) 228-312 | O21: =VLOOKUP($N21,Herbicide_Data!$A$1:$L$61,9) -> 2,4-D, dimethylamine salt; Dicamba, dimethylamine salt;Mecoprop-p (MCPP-p), dimethylamine salt | P21: =VLOOKUP($N21,Herbicide_Data!$A$1:$P$61,13) -> 24 | Q21: =P21*($H21/43560) -> 0.99173554 | R21: =IF($G21=("Fall (pre/post emerge)"),"Resolute 4Fl (100-1139)",IF($G21=("Spring Preemerge (Jan)"),"Resolute 4Fl (100-1139)",IF($G21=("Spring Preemerge (Apr)"),"Certinty Turf 59639-226",""))) -> Resolute 4Fl (100-1139) | S21: =VLOOKUP($R21,Herbicide_Data!$A$1:$L$61,9) -> Prodiamine | T21: =VLOOKUP($R21,Herbicide_Data!$A$1:$Q$61,13) -> 16 | U21: =T21*($H21/43560) -> 0.66115702 | V21: =IF($G21 = ("Preemerge"),"MSM Turf 228-373") -> FALSE | W21: =VLOOKUP($V21,Herbicide_Data!$A$1:$L$17,9) -> #N/A | X21: =VLOOKUP($V21,Herbicide_Data!$A$1:$L$17,12) -> #N/A | Y21: =X21*($H21/43560) -> #N/A | AH21: =IF($G21 = ("Spring Preemerge (Jan)"),"Surfactant") -> Surfactant | AI21: =VLOOKUP($AH21,Herbicide_Data!$A$1:$Q$61,13) -> 12.8 | AJ21: =AI21*($H21/43560) -> 0.52892562
A22: Elliot Smith | B22: 45710 | C22: 0.625 | D22: =C22+0.0208333 -> 0.6458333 | E22: Matthew Stowers | F22: =IFERROR(VLOOKUP(E22,Data!A$2:B$5,2,TRUE), "") -> 48160 | G22: Spring Preemerge (Jan) | H22: =IFERROR(VLOOKUP(A22,Customer_Data!$A$1:$P$114,8,TRUE),"") -> 13500 | J22: =IF($G22=("Fall (pre/post emerge)"),"Princep Liquid (100-526)", IF($G22=("Fertilize"),"Harrell's 34-0-5",IF($G22=("Spot Treat"),"Outrider (59639-223)",""))) | K22: =(VLOOKUP($J22,Herbicide_Data!$A$1:$L$61,9,TRUE)) -> #N/A | L22: =VLOOKUP($J22,Herbicide_Data!$A$1:$L$61,12,TRUE) -> #N/A | M22: =L22*(H22/43560) -> #N/A | N22: =IF($G22=("Fall (pre/post emerge)"),"Triplet SF (3-Way) 228-312",IF($G22=("Spring Preemerge (Jan)"),"Triplet SF (3-Way) 228-312",IF($G22=("Spring Preemerge (Apr)"),"Triplet SF (3-Way) 228-312",""))) -> Triplet SF (3-Way) 228-312 | O22: =VLOOKUP($N22,Herbicide_Data!$A$1:$L$61,9) -> 2,4-D, dimethylamine salt; Dicamba, dimethylamine salt;Mecoprop-p (MCPP-p), dimethylamine salt | P22: =VLOOKUP($N22,Herbicide_Data!$A$1:$P$61,13) -> 24 | Q22: =P22*($H22/43560) -> 7.4380165 | R22: =IF($G22=("Fall (pre/post emerge)"),"Resolute 4Fl (100-1139)",IF($G22=("Spring Preemerge (Jan)"),"Resolute 4Fl (100-1139)",IF($G22=("Spring Preemerge (Apr)"),"Certinty Turf 59639-226",""))) -> Resolute 4Fl (100-1139) | S22: =VLOOKUP($R22,Herbicide_Data!$A$1:$L$61,9) -> Prodiamine | T22: =VLOOKUP($R22,Herbicide_Data!$A$1:$Q$61,13) -> 16 | U22: =T22*($H22/43560) -> 4.9586777 | V22: =IF($G22 = ("Preemerge"),"MSM Turf 228-373") -> FALSE | W22: =VLOOKUP($V22,Herbicide_Data!$A$1:$L$17,9) -> #N/A | X22: =VLOOKUP($V22,Herbicide_Data!$A$1:$L$17,12) -> #N/A | Y22: =X22*($H22/43560) -> #N/A | AH22: =IF($G22 = ("Spring Preemerge (Jan)"),"Surfactant") -> Surfactant | AI22: =VLOOKUP($AH22,Herbicide_Data!$A$1:$Q$61,13) -> 12.8 | AJ22: =AI22*($H22/43560) -> 3.9669421
A23: Luther Stowers | B23: 45710 | C23: 0.64583333 | D23: =C23+0.0208333 -> 0.66666663 | E23: Luther Stowers | F23: =IFERROR(VLOOKUP(E23,Data!A$2:B$5,2,TRUE), "") -> 48182 | G23: Spring Preemerge (Jan) | H23: =IFERROR(VLOOKUP(A23,Customer_Data!$A$1:$P$114,8,TRUE),"") -> 5361 | J23: =IF($G23=("Fall (pre/post emerge)"),"Princep Liquid (100-526)", IF($G23=("Fertilize"),"Harrell's 34-0-5",IF($G23=("Spot Treat"),"Outrider (59639-223)",""))) | K23: =(VLOOKUP($J23,Herbicide_Data!$A$1:$L$61,9,TRUE)) -> #N/A | L23: =VLOOKUP($J23,Herbicide_Data!$A$1:$L$61,12,TRUE) -> #N/A | M23: =L23*(H23/43560) -> #N/A | N23: =IF($G23=("Fall (pre/post emerge)"),"Triplet SF (3-Way) 228-312",IF($G23=("Spring Preemerge (Jan)"),"Triplet SF (3-Way) 228-312",IF($G23=("Spring Preemerge (Apr)"),"Triplet SF (3-Way) 228-312",""))) -> Triplet SF (3-Way) 228-312 | O23: =VLOOKUP($N23,Herbicide_Data!$A$1:$L$61,9) -> 2,4-D, dimethylamine salt; Dicamba, dimethylamine salt;Mecoprop-p (MCPP-p), dimethylamine salt | P23: =VLOOKUP($N23,Herbicide_Data!$A$1:$P$61,13) -> 24 | Q23: =P23*($H23/43560) -> 2.953719 | R23: =IF($G23=("Fall (pre/post emerge)"),"Resolute 4Fl (100-1139)",IF($G23=("Spring Preemerge (Jan)"),"Resolute 4Fl (100-1139)",IF($G23=("Spring Preemerge (Apr)"),"Certinty Turf 59639-226",""))) -> Resolute 4Fl (100-1139) | S23: =VLOOKUP($R23,Herbicide_Data!$A$1:$L$61,9) -> Prodiamine | T23: =VLOOKUP($R23,Herbicide_Data!$A$1:$Q$61,13) -> 16 | U23: =T23*($H23/43560) -> 1.969146 | V23: =IF($G23 = ("Preemerge"),"MSM Turf 228-373") -> FALSE | W23: =VLOOKUP($V23,Herbicide_Data!$A$1:$L$17,9) -> #N/A | X23: =VLOOKUP($V23,Herbicide_Data!$A$1:$L$17,12) -> #N/A | Y23: =X23*($H23/43560) -> #N/A | AH23: =IF($G23 = ("Spring Preemerge (Jan)"),"Surfactant") -> Surfactant | AI23: =VLOOKUP($AH23,Herbicide_Data!$A$1:$Q$61,13) -> 12.8 | AJ23: =AI23*($H23/43560) -> 1.5753168
A24: Max Brian | B24: 45726 | C24: 0.72916667 | D24: =C24+0.0208333 -> 0.74999997 | E24: Matthew Stowers | F24: =IFERROR(VLOOKUP(E24,Data!A$2:B$5,2,TRUE), "") -> 48160 | G24: Spring Preemerge (Jan) | H24: =IFERROR(VLOOKUP(A24,Customer_Data!$A$1:$P$114,8,TRUE),"") -> 4670 | J24: =IF($G24=("Fall (pre/post emerge)"),"Princep Liquid (100-526)", IF($G24=("Fertilize"),"Harrell's 34-0-5",IF($G24=("Spot Treat"),"Outrider (59639-223)",""))) | K24: =(VLOOKUP($J24,Herbicide_Data!$A$1:$L$61,9,TRUE)) -> #N/A | L24: =VLOOKUP($J24,Herbicide_Data!$A$1:$L$61,12,TRUE) -> #N/A | M24: =L24*(H24/43560) -> #N/A | N24: =IF($G24=("Fall (pre/post emerge)"),"Triplet SF (3-Way) 228-312",IF($G24=("Spring Preemerge (Jan)"),"Triplet SF (3-Way) 228-312",IF($G24=("Spring Preemerge (Apr)"),"Triplet SF (3-Way) 228-312",""))) -> Triplet SF (3-Way) 228-312 | O24: =VLOOKUP($N24,Herbicide_Data!$A$1:$L$61,9) -> 2,4-D, dimethylamine salt; Dicamba, dimethylamine salt;Mecoprop-p (MCPP-p), dimethylamine salt | P24: =VLOOKUP($N24,Herbicide_Data!$A$1:$P$61,13) -> 24 | Q24: =P24*($H24/43560) -> 2.5730028 | R24: =IF($G24=("Fall (pre/post emerge)"),"Resolute 4Fl (100-1139)",IF($G24=("Spring Preemerge (Jan)"),"Resolute 4Fl (100-1139)",IF($G24=("Spring Preemerge (Apr)"),"Certinty Turf 59639-226",""))) -> Resolute 4Fl (100-1139) | S24: =VLOOKUP($R24,Herbicide_Data!$A$1:$L$61,9) -> Prodiamine | T24: =VLOOKUP($R24,Herbicide_Data!$A$1:$Q$61,13) -> 16 | U24: =T24*($H24/43560) -> 1.7153352 | V24: =IF($G24 = ("Preemerge"),"MSM Turf 228-373") -> FALSE | W24: =VLOOKUP($V24,Herbicide_Data!$A$1:$L$17,9) -> #N/A | X24: =VLOOKUP($V24,Herbicide_Data!$A$1:$L$17,12) -> #N/A | Y24: =X24*($H24/43560) -> #N/A | AH24: =IF($G24 = ("Spring Preemerge (Jan)"),"Surfactant") -> Surfactant | AI24: =VLOOKUP($AH24,Herbicide_Data!$A$1:$Q$61,13) -> 12.8 | AJ24: =AI24*($H24/43560) -> 1.3722681
A25: Troy Stokes | B25: 45726 | C25: 0.75 | D25: =C25+0.0208333 -> 0.7708333 | E25: Matthew Stowers | F25: =IFERROR(VLOOKUP(E25,Data!A$2:B$5,2,TRUE), "") -> 48160 | G25: Spring Preemerge (Jan) | H25: =IFERROR(VLOOKUP(A25,Customer_Data!$A$1:$P$114,8,TRUE),"") -> 9000 | J25: =IF($G25=("Fall (pre/post emerge)"),"Princep Liquid (100-526)", IF($G25=("Fertilize"),"Harrell's 34-0-5",IF($G25=("Spot Treat"),"Outrider (59639-223)",""))) | K25: =(VLOOKUP($J25,Herbicide_Data!$A$1:$L$61,9,TRUE)) -> #N/A | L25: =VLOOKUP($J25,Herbicide_Data!$A$1:$L$61,12,TRUE) -> #N/A | M25: =L25*(H25/43560) -> #N/A | N25: =IF($G25=("Fall (pre/post emerge)"),"Triplet SF (3-Way) 228-312",IF($G25=("Spring Preemerge (Jan)"),"Triplet SF (3-Way) 228-312",IF($G25=("Spring Preemerge (Apr)"),"Triplet SF (3-Way) 228-312",""))) -> Triplet SF (3-Way) 228-312 | O25: =VLOOKUP($N25,Herbicide_Data!$A$1:$L$61,9) -> 2,4-D, dimethylamine salt; Dicamba, dimethylamine salt;Mecoprop-p (MCPP-p), dimethylamine salt | P25: =VLOOKUP($N25,Herbicide_Data!$A$1:$P$61,13) -> 24 | Q25: =P25*($H25/43560) -> 4.9586777 | R25: =IF($G25=("Fall (pre/post emerge)"),"Resolute 4Fl (100-1139)",IF($G25=("Spring Preemerge (Jan)"),"Resolute 4Fl (100-1139)",IF($G25=("Spring Preemerge (Apr)"),"Certinty Turf 59639-226",""))) -> Resolute 4Fl (100-1139) | S25: =VLOOKUP($R25,Herbicide_Data!$A$1:$L$61,9) -> Prodiamine | T25: =VLOOKUP($R25,Herbicide_Data!$A$1:$Q$61,13) -> 16 | U25: =T25*($H25/43560) -> 3.3057851 | V25: =IF($G25 = ("Preemerge"),"MSM Turf 228-373") -> FALSE | W25: =VLOOKUP($V25,Herbicide_Data!$A$1:$L$17,9) -> #N/A | X25: =VLOOKUP($V25,Herbicide_Data!$A$1:$L$17,12) -> #N/A | Y25: =X25*($H25/43560) -> #N/A | AH25: =IF($G25 = ("Spring Preemerge (Jan)"),"Surfactant") -> Surfactant | AI25: =VLOOKUP($AH25,Herbicide_Data!$A$1:$Q$61,13) -> 12.8 | AJ25: =AI25*($H25/43560) -> 2.6446281
A26: Riley Bennett | B26: 45726 | C26: 0.77083333 | D26: =C26+0.0208333 -> 0.79166663 | E26: Matthew Stowers | F26: =IFERROR(VLOOKUP(E26,Data!A$2:B$5,2,TRUE), "") -> 48160 | G26: Spring Preemerge (Jan) | H26: =IFERROR(VLOOKUP(A26,Customer_Data!$A$1:$P$114,8,TRUE),"") -> 7500 | J26: =IF($G26=("Fall (pre/post emerge)"),"Princep Liquid (100-526)", IF($G26=("Fertilize"),"Harrell's 34-0-5",IF($G26=("Spot Treat"),"Outrider (59639-223)",""))) | K26: =(VLOOKUP($J26,Herbicide_Data!$A$1:$L$61,9,TRUE)) -> #N/A | L26: =VLOOKUP($J26,Herbicide_Data!$A$1:$L$61,12,TRUE) -> #N/A | M26: =L26*(H26/43560) -> #N/A | N26: =IF($G26=("Fall (pre/post emerge)"),"Triplet SF (3-Way) 228-312",IF($G26=("Spring Preemerge (Jan)"),"Triplet SF (3-Way) 228-312",IF($G26=("Spring Preemerge (Apr)"),"Triplet SF (3-Way) 228-312",""))) -> Triplet SF (3-Way) 228-312 | O26: =VLOOKUP($N26,Herbicide_Data!$A$1:$L$61,9) -> 2,4-D, dimethylamine salt; Dicamba, dimethylamine salt;Mecoprop-p (MCPP-p), dimethylamine salt | P26: =VLOOKUP($N26,Herbicide_Data!$A$1:$P$61,13) -> 24 | Q26: =P26*($H26/43560) -> 4.1322314 | R26: =IF($G26=("Fall (pre/post emerge)"),"Resolute 4Fl (100-1139)",IF($G26=("Spring Preemerge (Jan)"),"Resolute 4Fl (100-1139)",IF($G26=("Spring Preemerge (Apr)"),"Certinty Turf 59639-226",""))) -> Resolute 4Fl (100-1139) | S26: =VLOOKUP($R26,Herbicide_Data!$A$1:$L$61,9) -> Prodiamine | T26: =VLOOKUP($R26,Herbicide_Data!$A$1:$Q$61,13) -> 16 | U26: =T26*($H26/43560) -> 2.7548209 | V26: =IF($G26 = ("Preemerge"),"MSM Turf 228-373") -> FALSE | W26: =VLOOKUP($V26,Herbicide_Data!$A$1:$L$17,9) -> #N/A | X26: =VLOOKUP($V26,Herbicide_Data!$A$1:$L$17,12) -> #N/A | Y26: =X26*($H26/43560) -> #N/A | AH26: =IF($G26 = ("Spring Preemerge (Jan)"),"Surfactant") -> Surfactant | AI26: =VLOOKUP($AH26,Herbicide_Data!$A$1:$Q$61,13) -> 12.8 | AJ26: =AI26*($H26/43560) -> 2.2038567
A27: Danny Cooper | B27: 45727 | C27: 0.75 | D27: =C27+0.0208333 -> 0.7708333 | E27: Matthew Stowers | F27: =IFERROR(VLOOKUP(E27,Data!A$2:B$5,2,TRUE), "") -> 48160 | G27: Spring Preemerge (Jan) | H27: =IFERROR(VLOOKUP(A27,Customer_Data!$A$1:$P$114,8,TRUE),"") -> 7000 | J27: =IF($G27=("Fall (pre/post emerge)"),"Princep Liquid (100-526)", IF($G27=("Fertilize"),"Harrell's 34-0-5",IF($G27=("Spot Treat"),"Outrider (59639-223)",""))) | K27: =(VLOOKUP($J27,Herbicide_Data!$A$1:$L$61,9,TRUE)) -> #N/A | L27: =VLOOKUP($J27,Herbicide_Data!$A$1:$L$61,12,TRUE) -> #N/A | M27: =L27*(H27/43560) -> #N/A | N27: =IF($G27=("Fall (pre/post emerge)"),"Triplet SF (3-Way) 228-312",IF($G27=("Spring Preemerge (Jan)"),"Triplet SF (3-Way) 228-312",IF($G27=("Spring Preemerge (Apr)"),"Triplet SF (3-Way) 228-312",""))) -> Triplet SF (3-Way) 228-312 | O27: =VLOOKUP($N27,Herbicide_Data!$A$1:$L$61,9) -> 2,4-D, dimethylamine salt; Dicamba, dimethylamine salt;Mecoprop-p (MCPP-p), dimethylamine salt | P27: =VLOOKUP($N27,Herbicide_Data!$A$1:$P$61,13) -> 24 | Q27: =P27*($H27/43560) -> 3.8567493 | R27: =IF($G27=("Fall (pre/post emerge)"),"Resolute 4Fl (100-1139)",IF($G27=("Spring Preemerge (Jan)"),"Resolute 4Fl (100-1139)",IF($G27=("Spring Preemerge (Apr)"),"Certinty Turf 59639-226",""))) -> Resolute 4Fl (100-1139) | S27: =VLOOKUP($R27,Herbicide_Data!$A$1:$L$61,9) -> Prodiamine | T27: =VLOOKUP($R27,Herbicide_Data!$A$1:$Q$61,13) -> 16 | U27: =T27*($H27/43560) -> 2.5711662 | V27: =IF($G27 = ("Preemerge"),"MSM Turf 228-373") -> FALSE | W27: =VLOOKUP($V27,Herbicide_Data!$A$1:$L$17,9) -> #N/A | X27: =VLOOKUP($V27,Herbicide_Data!$A$1:$L$17,12) -> #N/A | Y27: =X27*($H27/43560) -> #N/A | AH27: =IF($G27 = ("Spring Preemerge (Jan)"),"Surfactant") -> Surfactant | AI27: =VLOOKUP($AH27,Herbicide_Data!$A$1:$Q$61,13) -> 12.8 | AJ27: =AI27*($H27/43560) -> 2.056933
A28: Seth Simmons | B28: 45735 | C28: 0.72916667 | D28: =C28+0.0208333 -> 0.74999997 | E28: Matthew Stowers | F28: =IFERROR(VLOOKUP(E28,Data!A$2:B$5,2,TRUE), "") -> 48160 | G28: Spring Preemerge (Jan) | H28: =IFERROR(VLOOKUP(A28,Customer_Data!$A$1:$P$114,8,TRUE),"") -> 6500 | J28: =IF($G28=("Fall (pre/post emerge)"),"Princep Liquid (100-526)", IF($G28=("Fertilize"),"Harrell's 34-0-5",IF($G28=("Spot Treat"),"Outrider (59639-223)",""))) | K28: =(VLOOKUP($J28,Herbicide_Data!$A$1:$L$61,9,TRUE)) -> #N/A | L28: =VLOOKUP($J28,Herbicide_Data!$A$1:$L$61,12,TRUE) -> #N/A | M28: =L28*(H28/43560) -> #N/A | N28: =IF($G28=("Fall (pre/post emerge)"),"Triplet SF (3-Way) 228-312",IF($G28=("Spring Preemerge (Jan)"),"Triplet SF (3-Way) 228-312",IF($G28=("Spring Preemerge (Apr)"),"Triplet SF (3-Way) 228-312",""))) -> Triplet SF (3-Way) 228-312 | O28: =VLOOKUP($N28,Herbicide_Data!$A$1:$L$61,9) -> 2,4-D, dimethylamine salt; Dicamba, dimethylamine salt;Mecoprop-p (MCPP-p), dimethylamine salt | P28: =VLOOKUP($N28,Herbicide_Data!$A$1:$P$61,13) -> 24 | Q28: =P28*($H28/43560) -> 3.5812672 | R28: =IF($G28=("Fall (pre/post emerge)"),"Resolute 4Fl (100-1139)",IF($G28=("Spring Preemerge (Jan)"),"Resolute 4Fl (100-1139)",IF($G28=("Spring Preemerge (Apr)"),"Certinty Turf 59639-226",""))) -> Resolute 4Fl (100-1139) | S28: =VLOOKUP($R28,Herbicide_Data!$A$1:$L$61,9) -> Prodiamine | T28: =VLOOKUP($R28,Herbicide_Data!$A$1:$Q$61,13) -> 16 | U28: =T28*($H28/43560) -> 2.3875115 | V28: =IF($G28 = ("Preemerge"),"MSM Turf 228-373") -> FALSE | W28: =VLOOKUP($V28,Herbicide_Data!$A$1:$L$17,9) -> #N/A | X28: =VLOOKUP($V28,Herbicide_Data!$A$1:$L$17,12) -> #N/A | Y28: =X28*($H28/43560) -> #N/A | AH28: =IF($G28 = ("Spring Preemerge (Jan)"),"Surfactant") -> Surfactant | AI28: =VLOOKUP($AH28,Herbicide_Data!$A$1:$Q$61,13) -> 12.8 | AJ28: =AI28*($H28/43560) -> 1.9100092
A29: Steve Edwards | B29: 45735 | C29: 0.75 | D29: =C29+0.0208333 -> 0.7708333 | E29: Matthew Stowers | F29: =IFERROR(VLOOKUP(E29,Data!A$2:B$5,2,TRUE), "") -> 48160 | G29: Spring Preemerge (Jan) | H29: =IFERROR(VLOOKUP(A29,Customer_Data!$A$1:$P$114,8,TRUE),"") -> 9000 | J29: =IF($G29=("Fall (pre/post emerge)"),"Princep Liquid (100-526)", IF($G29=("Fertilize"),"Harrell's 34-0-5",IF($G29=("Spot Treat"),"Outrider (59639-223)",""))) | K29: =(VLOOKUP($J29,Herbicide_Data!$A$1:$L$61,9,TRUE)) -> #N/A | L29: =VLOOKUP($J29,Herbicide_Data!$A$1:$L$61,12,TRUE) -> #N/A | M29: =L29*(H29/43560) -> #N/A | N29: =IF($G29=("Fall (pre/post emerge)"),"Triplet SF (3-Way) 228-312",IF($G29=("Spring Preemerge (Jan)"),"Triplet SF (3-Way) 228-312",IF($G29=("Spring Preemerge (Apr)"),"Triplet SF (3-Way) 228-312",""))) -> Triplet SF (3-Way) 228-312 | O29: =VLOOKUP($N29,Herbicide_Data!$A$1:$L$61,9) -> 2,4-D, dimethylamine salt; Dicamba, dimethylamine salt;Mecoprop-p (MCPP-p), dimethylamine salt | P29: =VLOOKUP($N29,Herbicide_Data!$A$1:$P$61,13) -> 24 | Q29: =P29*($H29/43560) -> 4.9586777 | R29: =IF($G29=("Fall (pre/post emerge)"),"Resolute 4Fl (100-1139)",IF($G29=("Spring Preemerge (Jan)"),"Resolute 4Fl (100-1139)",IF($G29=("Spring Preemerge (Apr)"),"Certinty Turf 59639-226",""))) -> Resolute 4Fl (100-1139) | S29: =VLOOKUP($R29,Herbicide_Data!$A$1:$L$61,9) -> Prodiamine | T29: =VLOOKUP($R29,Herbicide_Data!$A$1:$Q$61,13) -> 16 | U29: =T29*($H29/43560) -> 3.3057851 | V29: =IF($G29 = ("Preemerge"),"MSM Turf 228-373") -> FALSE | W29: =VLOOKUP($V29,Herbicide_Data!$A$1:$L$17,9) -> #N/A | X29: =VLOOKUP($V29,Herbicide_Data!$A$1:$L$17,12) -> #N/A | Y29: =X29*($H29/43560) -> #N/A | AH29: =IF($G29 = ("Spring Preemerge (Jan)"),"Surfactant") -> Surfactant | AI29: =VLOOKUP($AH29,Herbicide_Data!$A$1:$Q$61,13) -> 12.8 | AJ29: =AI29*($H29/43560) -> 2.6446281
A30: Gay Grantham | B30: 45735 | C30: 0.79166667 | D30: =C30+0.0208333 -> 0.81249997 | E30: Matthew Stowers | F30: =IFERROR(VLOOKUP(E30,Data!A$2:B$5,2,TRUE), "") -> 48160 | G30: Spring Preemerge (Jan) | H30: =IFERROR(VLOOKUP(A30,Customer_Data!$A$1:$P$114,8,TRUE),"") -> 5900 | J30: =IF($G30=("Fall (pre/post emerge)"),"Princep Liquid (100-526)", IF($G30=("Fertilize"),"Harrell's 34-0-5",IF($G30=("Spot Treat"),"Outrider (59639-223)",""))) | K30: =(VLOOKUP($J30,Herbicide_Data!$A$1:$L$61,9,TRUE)) -> #N/A | L30: =VLOOKUP($J30,Herbicide_Data!$A$1:$L$61,12,TRUE) -> #N/A | M30: =L30*(H30/43560) -> #N/A | N30: =IF($G30=("Fall (pre/post emerge)"),"Triplet SF (3-Way) 228-312",IF($G30=("Spring Preemerge (Jan)"),"Triplet SF (3-Way) 228-312",IF($G30=("Spring Preemerge (Apr)"),"Triplet SF (3-Way) 228-312",""))) -> Triplet SF (3-Way) 228-312 | O30: =VLOOKUP($N30,Herbicide_Data!$A$1:$L$61,9) -> 2,4-D, dimethylamine salt; Dicamba, dimethylamine salt;Mecoprop-p (MCPP-p), dimethylamine salt | P30: =VLOOKUP($N30,Herbicide_Data!$A$1:$P$61,13) -> 24 | Q30: =P30*($H30/43560) -> 3.2506887 | R30: =IF($G30=("Fall (pre/post emerge)"),"Resolute 4Fl (100-1139)",IF($G30=("Spring Preemerge (Jan)"),"Resolute 4Fl (100-1139)",IF($G30=("Spring Preemerge (Apr)"),"Certinty Turf 59639-226",""))) -> Resolute 4Fl (100-1139) | S30: =VLOOKUP($R30,Herbicide_Data!$A$1:$L$61,9) -> Prodiamine | T30: =VLOOKUP($R30,Herbicide_Data!$A$1:$Q$61,13) -> 16 | U30: =T30*($H30/43560) -> 2.1671258 | V30: =IF($G30 = ("Preemerge"),"MSM Turf 228-373") -> FALSE | W30: =VLOOKUP($V30,Herbicide_Data!$A$1:$L$17,9) -> #N/A | X30: =VLOOKUP($V30,Herbicide_Data!$A$1:$L$17,12) -> #N/A | Y30: =X30*($H30/43560) -> #N/A | AH30: =IF($G30 = ("Spring Preemerge (Jan)"),"Surfactant") -> Surfactant | AI30: =VLOOKUP($AH30,Herbicide_Data!$A$1:$Q$61,13) -> 12.8 | AJ30: =AI30*($H30/43560) -> 1.7337006
A31: Max Brian | B31: 45765 | C31: 0.625 | D31: =C31+0.0208333 -> 0.6458333 | E31: Matthew Stowers | F31: =IFERROR(VLOOKUP(E31,Data!A$2:B$5,2,TRUE), "") -> 48160 | G31: Spring Preemerge (Apr) | H31: =IFERROR(VLOOKUP(A31,Customer_Data!$A$1:$P$114,8,TRUE),"") -> 4670 | J31: =IF($G31=("Fall (pre/post emerge)"),"Princep Liquid (100-526)", IF($G31=("Fertilize"),"Harrell's 34-0-5",IF($G31=("Spot Treat"),"Outrider (59639-223)",""))) | K31: =(VLOOKUP($J31,Herbicide_Data!$A$1:$L$61,9,TRUE)) -> #N/A | L31: =VLOOKUP($J31,Herbicide_Data!$A$1:$L$61,12,TRUE) -> #N/A | M31: =L31*(H31/43560) -> #N/A | N31: =IF($G31=("Fall (pre/post emerge)"),"Triplet SF (3-Way) 228-312",IF($G31=("Spring Preemerge (Jan)"),"Triplet SF (3-Way) 228-312",IF($G31=("Spring Preemerge (Apr)"),"Triplet SF (3-Way) 228-312",""))) -> Triplet SF (3-Way) 228-312 | O31: =VLOOKUP($N31,Herbicide_Data!$A$1:$L$61,9) -> 2,4-D, dimethylamine salt; Dicamba, dimethylamine salt;Mecoprop-p (MCPP-p), dimethylamine salt | P31: =VLOOKUP($N31,Herbicide_Data!$A$1:$P$61,13) -> 24 | Q31: =P31*($H31/43560) -> 2.5730028 | R31: =IF($G31=("Fall (pre/post emerge)"),"Resolute 4Fl (100-1139)",IF($G31=("Spring Preemerge (Jan)"),"Resolute 4Fl (100-1139)",IF($G31=("Spring Preemerge (Apr)"),"Certinty Turf 59639-226",""))) -> Certinty Turf 59639-226 | S31: =VLOOKUP($R31,Herbicide_Data!$A$1:$L$61,9) -> Sulfosulfuron | T31: =VLOOKUP($R31,Herbicide_Data!$A$1:$Q$61,13) -> 0 | U31: =T31*($H31/43560) -> 0 | V31: =IF($G31 = ("Preemerge"),"MSM Turf 228-373") -> FALSE | W31: =VLOOKUP($V31,Herbicide_Data!$A$1:$L$17,9) -> #N/A | X31: =VLOOKUP($V31,Herbicide_Data!$A$1:$L$17,12) -> #N/A | Y31: =X31*($H31/43560) -> #N/A | AH31: =IF($G31=("Spring Preemerge (Jan)"),"Surfactant",IF($G31=("Spring Preemerge (Apr)"),"Surfactant","")) -> Surfactant | AI31: =VLOOKUP($AH31,Herbicide_Data!$A$1:$Q$61,13) -> 12.8 | AJ31: =AI31*($H31/43560) -> 1.3722681
A32: Troy Stokes | B32: 45765 | C32: 0.66666667 | D32: =C32+0.0208333 -> 0.68749997 | E32: Matthew Stowers | F32: =IFERROR(VLOOKUP(E32,Data!A$2:B$5,2,TRUE), "") -> 48160 | G32: Spring Preemerge (Apr) | H32: =IFERROR(VLOOKUP(A32,Customer_Data!$A$1:$P$114,8,TRUE),"") -> 9000 | J32: =IF($G32=("Fall (pre/post emerge)"),"Princep Liquid (100-526)", IF($G32=("Fertilize"),"Harrell's 34-0-5",IF($G32=("Spot Treat"),"Outrider (59639-223)",""))) | K32: =(VLOOKUP($J32,Herbicide_Data!$A$1:$L$61,9,TRUE)) -> #N/A | L32: =VLOOKUP($J32,Herbicide_Data!$A$1:$L$61,12,TRUE) -> #N/A | M32: =L32*(H32/43560) -> #N/A | N32: =IF($G32=("Fall (pre/post emerge)"),"Triplet SF (3-Way) 228-312",IF($G32=("Spring Preemerge (Jan)"),"Triplet SF (3-Way) 228-312",IF($G32=("Spring Preemerge (Apr)"),"Triplet SF (3-Way) 228-312",""))) -> Triplet SF (3-Way) 228-312 | O32: =VLOOKUP($N32,Herbicide_Data!$A$1:$L$61,9) -> 2,4-D, dimethylamine salt; Dicamba, dimethylamine salt;Mecoprop-p (MCPP-p), dimethylamine salt | P32: =VLOOKUP($N32,Herbicide_Data!$A$1:$P$61,13) -> 24 | Q32: =P32*($H32/43560) -> 4.9586777 | R32: =IF($G32=("Fall (pre/post emerge)"),"Resolute 4Fl (100-1139)",IF($G32=("Spring Preemerge (Jan)"),"Resolute 4Fl (100-1139)",IF($G32=("Spring Preemerge (Apr)"),"Certinty Turf 59639-226",""))) -> Certinty Turf 59639-226 | S32: =VLOOKUP($R32,Herbicide_Data!$A$1:$L$61,9) -> Sulfosulfuron | T32: =VLOOKUP($R32,Herbicide_Data!$A$1:$Q$61,13) -> 0 | U32: =T32*($H32/43560) -> 0 | V32: =IF($G32 = ("Preemerge"),"MSM Turf 228-373") -> FALSE | W32: =VLOOKUP($V32,Herbicide_Data!$A$1:$L$17,9) -> #N/A | X32: =VLOOKUP($V32,Herbicide_Data!$A$1:$L$17,12) -> #N/A | Y32: =X32*($H32/43560) -> #N/A | AH32: =IF($G32=("Spring Preemerge (Jan)"),"Surfactant",IF($G32=("Spring Preemerge (Apr)"),"Surfactant","")) -> Surfactant | AI32: =VLOOKUP($AH32,Herbicide_Data!$A$1:$Q$61,13) -> 12.8 | AJ32: =AI32*($H32/43560) -> 2.6446281
